Workbook

Sheet Supuestos
A1: Lo que se supone para sacar el neto
A3: Comisión que cobran las plataformas | B3: 0.3
A4: Dato de Javi, cerrado el 22 sep 2026 en 30%. No es la tarifa publicada. Airbnb declara 20% en Experiencias, pero sobre esa comisión corre el IVA del 16% —que la deja en 23.2%— y encima van conversión de divisa y proceso de pago. Las demás plataformas hacen lo mismo. Cambia esta celda y toda la hoja Netos se recalcula.
A9: Qué es el neto de esta hoja
A10: Lo que le queda al operador después de la comisión de la plataforma. Es el mismo número que le puede dar a Sincrético: no le pedimos mejor precio que a las OTAs, le pedimos el mismo. Nosotros además lo repartimos con quien lo vende.
A15: De dónde salen los precios
A16: Captura de listados públicos del 15 de septiembre de 2026, en crm_guias y crm_guia_tours. 455 anuncios de 393 tours de 235 guías. Todo en pesos mexicanos.
A20: Moneda
A21: TODAS las cifras de este archivo están en PESOS MEXICANOS (MXN). Donde aparezca un importe en dólares se escribe USD de forma explícita. Los contratos de las plataformas sí usan dólares en algunos umbrales —Viator retiene liquidaciones por debajo de USD 50, Airbnb cobra un mínimo de USD 6 en Servicios—; esos son dólares, no pesos, y no se han convertido.

Sheet Netos
A1: Guía | B1: Tour | C1: Zona | D1: Plataforma | E1: Rating | F1: Reseñas | G1: PVP público (MXN) | H1: Neto para nosotros (MXN) | I1: Web | J1: Instagram | K1: Correo | L1: WhatsApp | M1: Liga del anuncio
A2: A Chef's Tour | B2: Tour gastronómico por la Ciudad de México con 12+ degustaciones | C2: Centro Histórico | D2: Viator | E2: 4.8 | F2: 6 | G2: 1558 | H2: =IF(G2="","",ROUND(G2*(1-Supuestos!$B$3),0)) -> 1091 | I2: https://achefstour.com/ | J2: @achefstour | K2: info@achefstour.com | M2: https://www.viator.com/es-MX/tours/Mexico-City/x/d628-69673P126
A3: Abril · Find Mexico | B3: Tour privado a pie por el centro de la Ciudad de México | C3: Centro Histórico | D3: Viator | F3: 0 | G3: 350 | H3: =IF(G3="","",ROUND(G3*(1-Supuestos!$B$3),0)) -> 245 | M3: https://www.viator.com/es-MX/tours/Mexico-City/x/d628-5517516P1
A4: Adrenaline | B4: Tepito Tour Mercados locales, comida callejera y Santa Muerte | C4: Centro Histórico | D4: Viator | F4: 0 | G4: 1715 | H4: =IF(G4="","",ROUND(G4*(1-Supuestos!$B$3),0)) -> 1201 | M4: https://www.viator.com/es-MX/tours/Mexico-City/x/d628-91751P313
A5: Ady — Experience Mexico from the center: Legend and hi | B5: Experience Mexico from the center: Legend and history | C5: Centro Histórico | D5: Airbnb Experiences | E5: 5 | F5: 1 | G5: 758 | H5: =IF(G5="","",ROUND(G5*(1-Supuestos!$B$3),0)) -> 531 | M5: https://www.airbnb.com/experiences/6461639
A6: Alejandro Torres Rivera | B6: Ride a bike and cable car through Chapultepec | C6: Bici · varias colonias | D6: Airbnb Experiences | E6: 5 | F6: 4 | G6: 1480 | H6: =IF(G6="","",ROUND(G6*(1-Supuestos!$B$3),0)) -> 1036 | M6: https://www.airbnb.com/experiences/4763785
A7: ALEMEX TOURS | B7: Ciudad de México: recorrido guiado por la ciudad desde el Parque Chapultepec hasta la avenida Paseo de la Reforma | C7: Reforma/Juárez | D7: Airbnb Experiences | F7: 0 | G7: 703 | H7: =IF(G7="","",ROUND(G7*(1-Supuestos!$B$3),0)) -> 492 | I7: https://www.alemex-tours.com/ | L7: 491792001731 | M7: https://www.airbnb.com/experiences/6941466
A8: ALEMEX TOURS | B8: Ciudad de México: recorrido guiado por la ciudad desde el Parque Chapultepec hasta la avenida Paseo de la Reforma | C8: Reforma/Juárez | D8: GetYourGuide | E8: 5 | F8: 10 | G8: 630 | H8: =IF(G8="","",ROUND(G8*(1-Supuestos!$B$3),0)) -> 441 | I8: https://www.alemex-tours.com/ | L8: 491792001731 | M8: https://www.getyourguide.com/es-mx/ciudad-de-mexico-l194/-t1108573/
A9: ALEMEX TOURS | B9: Ciudad de México: Recorrido histórico por el centro – De los aztecas a la metrópoli | C9: Centro Histórico | D9: GetYourGuide | E9: 5 | F9: 6 | G9: 675 | H9: =IF(G9="","",ROUND(G9*(1-Supuestos!$B$3),0)) -> 472 | I9: https://www.alemex-tours.com/ | L9: 491792001731 | M9: https://www.getyourguide.com/es-mx/ciudad-de-mexico-l194/-t1141787/
A10: ALEMEX TOURS | B10: Ciudad de México: Recorrido histórico por el centro – De los aztecas a la metrópoli | C10: Centro Histórico | D10: Airbnb Experiences | E10: 5 | F10: 2 | G10: 814 | H10: =IF(G10="","",ROUND(G10*(1-Supuestos!$B$3),0)) -> 570 | I10: https://www.alemex-tours.com/ | L10: 491792001731 | M10: https://www.airbnb.com/experiences/6913997
A11: ALEMEX TOURS | B11: Ciudad de México: Recorrido histórico por el centro – De los aztecas a la metrópoli | C11: Centro Histórico | D11: Viator | F11: 0 | G11: 850 | H11: =IF(G11="","",ROUND(G11*(1-Supuestos!$B$3),0)) -> 595 | I11: https://www.alemex-tours.com/ | L11: 491792001731 | M11: https://www.viator.com/es-MX/tours/Mexico-City/x/d628-5652165P2
A12: ALEMEX TOURS | B12: From the Park to the Boulevard: Chapultepec & Reforma | C12: Reforma/Juárez | D12: Airbnb Experiences | F12: 0 | G12: 703 | H12: =IF(G12="","",ROUND(G12*(1-Supuestos!$B$3),0)) -> 492 | I12: https://www.alemex-tours.com/ | L12: 491792001731 | M12: https://www.airbnb.com/experiences/6955761
A13: ALEMEX TOURS | B13: Historic Center: From the Aztecs to the Present | C13: Centro Histórico | D13: Airbnb Experiences | E13: 5 | F13: 2 | G13: 814 | H13: =IF(G13="","",ROUND(G13*(1-Supuestos!$B$3),0)) -> 570 | I13: https://www.alemex-tours.com/ | L13: 491792001731 | M13: https://www.airbnb.com/experiences/6928261
A14: Alisa — Meet the ghosts of Mexico City | B14: Meet the ghosts of Mexico City | C14: Centro Histórico | D14: Airbnb Experiences | E14: 4.93 | F14: 509 | G14: 814 | H14: =IF(G14="","",ROUND(G14*(1-Supuestos!$B$3),0)) -> 570 | M14: https://www.airbnb.com/experiences/3111741
A15: ALOHA CDMX | B15: Noche de Barrio Tacos Mezcal y Música | C15: Centro Histórico | D15: Viator | F15: 0 | G15: 2600 | H15: =IF(G15="","",ROUND(G15*(1-Supuestos!$B$3),0)) -> 1820 | M15: https://www.viator.com/es-MX/tours/Mexico-City/x/d628-427760P4
A16: Amazing photoshoot in downtown Mexico City | B16: Explorando el centro de la Ciudad de México a través de la lente | C16: Centro Histórico | D16: Viator | F16: 0 | G16: 2000 | H16: =IF(G16="","",ROUND(G16*(1-Supuestos!$B$3),0)) -> 1400 | M16: https://www.viator.com/es-MX/tours/Mexico-City/x/d628-5599437P2
A17: Amigo Tours | B17: Ciudad de México: tour nocturno a pie con opción de Torre Latino | C17: Centro Histórico | D17: GetYourGuide | E17: 3.65 | F17: 42 | G17: 617.39 | H17: =IF(G17="","",ROUND(G17*(1-Supuestos!$B$3),0)) -> 432 | I17: https://amigotours.com/ | J17: @amigo.tours | K17: cdmx@amigotours.com | L17: 525545638246 | M17: https://www.getyourguide.com/es-mx/ciudad-de-mexico-l194/-t409964/
A18: Amigo Tours | B18: Ciudad de México: tour nocturno a pie con opción de Torre Latino | C18: Centro Histórico | D18: Viator | E18: 4.3 | F18: 48 | G18: 630 | H18: =IF(G18="","",ROUND(G18*(1-Supuestos!$B$3),0)) -> 441 | I18: https://amigotours.com/ | J18: @amigo.tours | K18: cdmx@amigotours.com | L18: 525545638246 | M18: https://www.viator.com/es-MX/tours/Mexico-City/x/d628-5885P196
A19: Amigo Tours | B19: Ciudad de México: tour privado en bicicleta por el Bosque de Chapultepec | C19: Reforma/Juárez | D19: Viator | E19: 4.7 | F19: 24 | G19: 2118 | H19: =IF(G19="","",ROUND(G19*(1-Supuestos!$B$3),0)) -> 1483 | I19: https://amigotours.com/ | J19: @amigo.tours | K19: cdmx@amigotours.com | L19: 525545638246 | M19: https://www.viator.com/es-MX/tours/Mexico-City/x/d628-5885P432
A20: Amigo Tours | B20: Ciudad de México: tour privado en bicicleta por el Bosque de Chapultepec | C20: Reforma/Juárez | D20: GetYourGuide | E20: 4.78 | F20: 16 | G20: 2418.09 | H20: =IF(G20="","",ROUND(G20*(1-Supuestos!$B$3),0)) -> 1693 | I20: https://amigotours.com/ | J20: @amigo.tours | K20: cdmx@amigotours.com | L20: 525545638246 | M20: https://www.getyourguide.com/es-mx/ciudad-de-mexico-l194/-t434289/
A21: Amigo Tours | B21: Day of the Dead Tour | C21: Centro Histórico | D21: Airbnb Experiences | F21: 0 | G21: 1517 | H21: =IF(G21="","",ROUND(G21*(1-Supuestos!$B$3),0)) -> 1062 | I21: https://amigotours.com/ | J21: @amigo.tours | K21: cdmx@amigotours.com | L21: 525545638246 | M21: https://www.airbnb.com/experiences/6951617
A22: Amigo Tours | B22: Edificios y palacios imperdibles de la Ciudad de México | C22: Centro Histórico | D22: GetYourGuide | E22: 4.36 | F22: 36 | G22: 823.18 | H22: =IF(G22="","",ROUND(G22*(1-Supuestos!$B$3),0)) -> 576 | I22: https://amigotours.com/ | J22: @amigo.tours | K22: cdmx@amigotours.com | L22: 525545638246 | M22: https://www.getyourguide.com/es-mx/ciudad-de-mexico-l194/-t433804/
A23: Amigo Tours | B23: Tour de Mercados Locales & Comida Exótica | C23: Centro Histórico | D23: Airbnb Experiences | E23: 4.5 | F23: 2 | G23: 1073 | H23: =IF(G23="","",ROUND(G23*(1-Supuestos!$B$3),0)) -> 751 | I23: https://amigotours.com/ | J23: @amigo.tours | K23: cdmx@amigotours.com | L23: 525545638246 | M23: https://www.airbnb.com/experiences/6952959
A24: Amigo Tours | B24: Tour de Mercados Locales & Comida Exótica | C24: Centro Histórico | D24: Viator | E24: 4.3 | F24: 23 | G24: 1103 | H24: =IF(G24="","",ROUND(G24*(1-Supuestos!$B$3),0)) -> 772 | I24: https://amigotours.com/ | J24: @amigo.tours | K24: cdmx@amigotours.com | L24: 525545638246 | M24: https://www.viator.com/es-MX/tours/Mexico-City/x/d628-5885P431
A25: Amigo Tours | B25: Tour por el Banco Nacional y los palacios de Ciudad de Mexico | C25: Centro Histórico | D25: Civitatis | E25: 4.65 | F25: 3 | G25: 4562 | H25: =IF(G25="","",ROUND(G25*(1-Supuestos!$B$3),0)) -> 3193 | I25: https://amigotours.com/ | J25: @amigo.tours | K25: cdmx@amigotours.com | L25: 525545638246 | M25: https://www.civitatis.com/es/ciudad-de-mexico/banco-nacional-palacios-ciudad-mexico/
A26: Ancient Tenochtitlán Tours | B26: Tour Ciudad de México Antigua : Degustación de Cacao & Historia Azteca en CDMX | C26: Centro Histórico | D26: Viator | E26: 4 | F26: 1 | G26: 1558 | H26: =IF(G26="","",ROUND(G26*(1-Supuestos!$B$3),0)) -> 1091 | M26: https://www.viator.com/es-MX/tours/Mexico-City/x/d628-5596307P2
A27: Andrea — Artistic and Cultural Tour in Tepito | B27: Artistic and Cultural Tour in Tepito | C27: Centro Histórico | D27: Airbnb Experiences | F27: 0 | G27: 870 | H27: =IF(G27="","",ROUND(G27*(1-Supuestos!$B$3),0)) -> 609 | M27: https://www.airbnb.com/experiences/6916169
A28: Andrés (Pintando la Revolución) | B28: Painting the Revolution: Murals, Markets, and Pulque | C28: Centro Histórico | D28: Airbnb Experiences | F28: 0 | G28: 666 | H28: =IF(G28="","",ROUND(G28*(1-Supuestos!$B$3),0)) -> 466 | M28: https://www.airbnb.com/experiences/7051320
A29: Andrés (Pintando la Revolución) | B29: Pintando la revolución Muralismo y pulque en CDMX | C29: Centro Histórico | D29: Viator | F29: 0 | G29: 700 | H29: =IF(G29="","",ROUND(G29*(1-Supuestos!$B$3),0)) -> 490 | M29: https://www.viator.com/es-MX/tours/Mexico-City/x/d628-5580793P4
A30: Andrés (Pintando la Revolución) | B30: Santa María la Rivera librería flotante, murales y pulque | C30: Centro Histórico | D30: Viator | F30: 0 | G30: 600 | H30: =IF(G30="","",ROUND(G30*(1-Supuestos!$B$3),0)) -> 420 | M30: https://www.viator.com/es-MX/tours/Mexico-City/x/d628-5580793P6
A31: Angel — A Food Tour of Historic Santa Maria la Ribera | B31: A Food Tour of Historic Santa Maria la Ribera | C31: Centro Histórico | D31: Airbnb Experiences | E31: 5 | F31: 16 | G31: 1314 | H31: =IF(G31="","",ROUND(G31*(1-Supuestos!$B$3),0)) -> 920 | M31: https://www.airbnb.com/experiences/6534668
A32: Angela Pilar — Mexico City Revealed Food and Culture Experience | B32: Mexico City Revealed Food and Culture Experience | C32: Centro Histórico | D32: Airbnb Experiences | F32: 0 | G32: 870 | H32: =IF(G32="","",ROUND(G32*(1-Supuestos!$B$3),0)) -> 609 | M32: https://www.airbnb.com/experiences/7117952
A33: Antonio — Trace mariachi legends in Garibaldi | B33: Trace mariachi legends in Garibaldi | C33: Centro Histórico | D33: Airbnb Experiences | F33: 0 | G33: 1628 | H33: =IF(G33="","",ROUND(G33*(1-Supuestos!$B$3),0)) -> 1140 | M33: https://www.airbnb.com/experiences/7252170
A34: Arc Tours | B34: Recorrido a Pie por el Templo Mayor y el Centro Histórico | C34: Centro Histórico | D34: Viator | F34: 0 | G34: 1200 | H34: =IF(G34="","",ROUND(G34*(1-Supuestos!$B$3),0)) -> 840 | M34: https://www.viator.com/es-MX/tours/Mexico-City/x/d628-484176P6
A35: Arte Para Todxs | B35: Diego Rivera & Bellas Artes: Mural Masterpieces | C35: Centro Histórico | D35: Airbnb Experiences | F35: 0 | G35: 1073 | H35: =IF(G35="","",ROUND(G35*(1-Supuestos!$B$3),0)) -> 751 | M35: https://www.airbnb.com/experiences/7224665
A36: Arte Para Todxs | B36: San Ildefonso: Where Muralism Began | C36: Centro Histórico | D36: Airbnb Experiences | F36: 0 | G36: 1073 | H36: =IF(G36="","",ROUND(G36*(1-Supuestos!$B$3),0)) -> 751 | M36: https://www.airbnb.com/experiences/7224702
A37: Artours CDMX | B37: Centro de la CDMX como Nunca lo Viste Historia y Secretos | C37: Centro Histórico | D37: Viator | E37: 5 | F37: 1 | G37: 1733 | H37: =IF(G37="","",ROUND(G37*(1-Supuestos!$B$3),0)) -> 1213 | M37: https://www.viator.com/es-MX/tours/Mexico-City/x/d628-5571656P3
A38: Aztec Action | B38: Ciudad de México: tour a pie por la historia del catolicismo con guía | C38: Centro Histórico | D38: GetYourGuide | F38: 0 | G38: 350 | H38: =IF(G38="","",ROUND(G38*(1-Supuestos!$B$3),0)) -> 245 | M38: https://www.getyourguide.com/es-mx/ciudad-de-mexico-l194/-t1362651/
A39: AztecAdvendTour | B39: Ciudad de México: Tour queer de comida y vida nocturna en Garibaldi y la calle Cuba | C39: Centro Histórico | D39: GetYourGuide | F39: 0 | G39: 2500 | H39: =IF(G39="","",ROUND(G39*(1-Supuestos!$B$3),0)) -> 1750 | M39: https://www.getyourguide.com/es-mx/ciudad-de-mexico-l194/-t1362189/
A40: AztecAdvendTour | B40: Crónicas del Centro: Historias Vivas de la Ciudad de México | C40: Centro Histórico | D40: GetYourGuide | E40: 5 | F40: 1 | G40: 980 | H40: =IF(G40="","",ROUND(G40*(1-Supuestos!$B$3),0)) -> 686 | M40: https://www.getyourguide.com/es-mx/ciudad-de-mexico-l194/-t1071997/
...

Sheet Por plataforma
A1: Plataforma | B1: Anuncios | C1: PVP promedio (MXN) | D1: Neto promedio (MXN)
A2: Airbnb Experiences | B2: =COUNTIF(Netos!$D:$D,A2) -> 136 | C2: =ROUND(AVERAGEIF(Netos!$D$2:$D$456,A2,Netos!$G$2:$G$456),0) -> 1203 | D2: =ROUND(AVERAGEIF(Netos!$D$2:$D$456,A2,Netos!$H$2:$H$456),0) -> 842
A3: Civitatis | B3: =COUNTIF(Netos!$D:$D,A3) -> 23 | C3: =ROUND(AVERAGEIF(Netos!$D$2:$D$456,A3,Netos!$G$2:$G$456),0) -> 2444 | D3: =ROUND(AVERAGEIF(Netos!$D$2:$D$456,A3,Netos!$H$2:$H$456),0) -> 1711
A4: GetYourGuide | B4: =COUNTIF(Netos!$D:$D,A4) -> 116 | C4: =ROUND(AVERAGEIF(Netos!$D$2:$D$456,A4,Netos!$G$2:$G$456),0) -> 2075 | D4: =ROUND(AVERAGEIF(Netos!$D$2:$D$456,A4,Netos!$H$2:$H$456),0) -> 1453
A5: Viator | B5: =COUNTIF(Netos!$D:$D,A5) -> 180 | C5: =ROUND(AVERAGEIF(Netos!$D$2:$D$456,A5,Netos!$G$2:$G$456),0) -> 1482 | D5: =ROUND(AVERAGEIF(Netos!$D$2:$D$456,A5,Netos!$H$2:$H$456),0) -> 1038
